Workbook

Sheet реестр 2026
A2: Реестр Международных выставок 2026 года
A4: № | B4: Название выставки | C4: Время проведения | D4: Дата проведения | E4: Размер площади | F4: Стоимость площади | G4: Валюта | H4: Стоимость стенда | I4: Валюта | J4: Участники выставки | K4: Сумма | L4: Валюта | M4: Прибыль | P4: евро | Q4: 13981
A5: 1 | B5: FITUR-2026 (Feria Internacional de Turismo) | C5: Madrid, Spain | D5: 21-25 января | E5: 150 кв м | F5: 33921 | G5: EURO | H5: 1620000000 | I5: Сум | J5: OOO "Samarkand Touristic Centre" | K5: 40000000 | L5: Сум | P5: дол | Q5: 11930
J6: OOO "TRAVEL ISTAN" | K6: 40000000 | P6: рубль | Q6: 163.03
J7: Samarcanda Adventures | K7: 40000000
J8: OOO "Premium Trans"/Orient Star | K8: 40000000
J9: OOO "ARCADA TRAVEL" | K9: 40000000
J10: OOO "El MUNDO TOUR" | K10: 40000000
J11: OOO "AVRUD" | K11: 40000000
J12: Zamin DMC | K12: 40000000
J13: Global EXPLORE/Uzbekistan Discovery | K13: 40000000 | Q13: =E15+H15+E19+H19+E28+H28+E33+H33+E37+H37+E45+H45+E54+H54+E60+H60+E77+H77+E87+H87+E96+H96+E101+H101+E107+H107+E112+H112 -> 1.9931853e+10
J14: "Uzbekistan Airways" | K14: 100000000
A15: Итог | E15: =F5*Q4 -> 474249501 | G15: Сум | H15: =H5 -> 1620000000 | I15: Сум | K15: =SUM(K5:K14) -> 460000000 | L15: =K15-H15-E15 -> -1634249501 | O15: =E15+H15 -> 2094249501 | Q15: =O15+[2]Sheet1!$O$16 -> 2.99582e+09
A16: 2 | B16: «Ferien Messe 2026» | C16: Vienna, Austria | D16: 15-18 января | E16: 60 кв м | F16: 9880.83 | G16: EURO | H16: 60000 | I16: EURO | J16: "SULTAN TRAVEL UZBEKISTAN" | K16: 10000000 | L16: Сум | Q16: =K15+K19+K28+K33+K37+K45+K54+K60+K77+K87+K96+K101+K107+K112 -> 2449500000
J17: "East Asia Point" | K17: 10000000
J18: OOO "Premium Trans"/Orient Star | K18: 10000000
A19: Итог | E19: =F16*Q4 -> 1.3814388e+08 | G19: Сум | H19: =H16*Q4 -> 838860000 | I19: Сум | K19: =SUM(K16:K18) -> 30000000 | L19: =K19-H19-E19 -> -9.4700388e+08 | Q19: =Q13-Q16 -> 1.7482353e+10
A20: 3 | B20: Travel and Adventure Show | C20: United States | D20: 25-26 января | E20: 55,7 кв м | F20: 26970 | G20: USD | H20: 139877.28 | I20: USD | J20: Zumrad travel | K20: 0 | L20: Сум
J21: Uzairways | K21: 0
J22: Tashkent travel hub | K22: 0
J23: Sogda tour | K23: 0
J24: Milliy tourism group | K24: 0
J25: Travel together | K25: 0
J26: Silk Road treasures | K26: 0
J27: Akbar travel | K27: 0
A28: Итог | E28: =F20*Q5 -> 321752100 | G28: Сум | H28: =H20*Q5 -> 1.668736e+09 | I28: Сум | K28: =SUM(K20:K27) -> 0 | L28: =K28-H28-E28 -> -1.9904881e+09
A29: 4 | B29: "BIT 2026" (Borsa Internazionale del Turismo) | C29: Milan, Italy | D29: 10-12 февраля | E29: 64 кв м | F29: 20005 | G29: EURO | H29: 4637000 | I29: Рубль | J29: OOO "FINANCE WORLD SERVICES" | K29: 15000000 | L29: Сум
J30: OOO AFSONA TRAVEL | K30: 15000000
J31: Zumrad Travel | K31: 7500000
J32: Anur Tour | K32: 15000000
A33: Итог | E33: =F29*Q4 -> 279689905 | G33: Сум | H33: =H29*Q6 -> 755970110 | I33: Сум | K33: =SUM(K29:K32) -> 52500000 | L33: =K33-H33-E33 -> -983160015
A34: 5 | B34: "Danish Travel show 2026" | C34: Herning, Denmark | D34: 20-22 февраля | E34: 48 кв м | F34: 8423.73 | G34: EURO | H34: 63500 | I34: EURO | J34: OOO "Premium Trans"/Orient Star | K34: 10000000 | L34: Сум
J35: "Miramax Travel Management" | K35: 10000000
J36: "Tashkent Travel Hub" | K36: 10000000
A37: Итог | E37: =F34*Q4 -> 1.1777217e+08 | G37: Сум | H37: =H34*Q4 -> 887793500 | I37: Сум | K37: =SUM(K34:K36) -> 30000000 | L37: =K37-H37-E37 -> -9.7556567e+08
A38: 6 | B38: "B-Travel 2026" | C38: Barcelona, Spain | D38: 20-22 марта | E38: 94 кв м | F38: 25941 | G38: EURO | H38: 64775 | I38: EURO | J38: OOO "Global Explore" | K38: 10000000 | L38: Сум
J39: OOO "El Mundo Tour" | K39: 10000000
J40: OOO "Samarkand Touristic Centre" | K40: 10000000
J41: OOO "Premium Trans"/Orient Star | K41: 10000000
J42: OOO "Zamin DMC" | K42: 10000000
...

Sheet FITUR-2026
A1: № | B1: Название выставки | C1: Дата проведения | D1: Размер площади | E1: Стоимость площади | F1: Валюта | G1: Стоимость стенда | H1: Валюта | I1: Участники выставки | J1: Сумма | K1: Валюта | L1: Прибыль
A2: 1 | B2: FITUR-2026 | C2: 21-25 января | D2: 150 кв м | E2: 33921 | F2: EURO | G2: 1620000000 | H2: Сум | I2: OOO "Samarkand Touristic Centre" | J2: 40000000 | K2: Сум
I3: OOO "TRAVEL ISTAN" | J3: 40000000 | N3: евро | O3: 13981
I4: Samarcanda Adventures | J4: 40000000
I5: OOO "Premium Trans"/Orient Star | J5: 40000000
I6: OOO "ARCADA TRAVEL" | J6: 40000000
I7: OOO "El MUNDO TOUR" | J7: 40000000
I8: OOO "AVRUD" | J8: 40000000
I9: Zamin DMC | J9: 40000000
I10: Global EXPLORE/Uzbekistan Discovery | J10: 40000000
I11: "Uzbekistan Airways" | J11: 100000000
A12: Итог | D12: =E2*O3 -> 474249501 | F12: Сум | G12: =G2 -> 1620000000 | H12: Сум | J12: =SUM(J2:J11) -> 460000000 | K12: =J12-G12-D12 -> -1634249501

Sheet "Ferrien Messe 2026"
A1: № | B1: Название выставки | C1: Дата проведения | D1: Размер площади | E1: Стоимость площади | F1: Валюта | G1: Стоимость стенда | H1: Валюта | I1: Участники выставки | J1: Сумма | K1: Валюта | L1: Прибыль
A2: 2 | B2: "Ferrien Messe 2026" | C2: 15-18 января | D2: 60 кв м | E2: 9880.83 | F2: EURO | G2: 60000 | H2: EURO | I2: "SULTAN TRAVEL UZBEKISTAN" | J2: 10000000 | K2: Сум | M2: евро | N2: 13981
I3: "East Asia Point" | J3: 10000000
I4: OOO "Premium Trans"/Orient Star | J4: 10000000
A5: Итог | D5: =E2*N2 -> 1.3814388e+08 | F5: Сум | G5: =G2*N2 -> 838860000 | H5: Сум | J5: =SUM(J2:J4) -> 30000000 | K5: =J5-G5-D5 -> -9.4700388e+08

Sheet Travel and Adventure
A1: № | B1: Название выставки | C1: Дата проведения | D1: Размер площади | E1: Стоимость площади | F1: Валюта | G1: Стоимость стенда | H1: Валюта | I1: Участники выставки | J1: Сумма | K1: Валюта | L1: Прибыль
A2: 3 | B2: Travel and Adventure Show Америка | C2: 25-26 января | D2: 55,7 кв м | E2: 26970 | F2: USD | G2: 139877.28 | H2: USD | I2: Zumrad travel | J2: 0 | K2: Сум
I3: Uzairways | J3: 0 | N3: дол | O3: 11930
I4: Tashkent travel hub | J4: 0
I5: Sogda tour | J5: 0
I6: Milliy tourism group | J6: 0
I7: Travel together | J7: 0
I8: Silk Road treasures | J8: 0
I9: Akbar travel | J9: 0
A10: Итог | D10: =E2*O3 -> 321752100 | F10: Сум | G10: =G2*O3 -> 1.668736e+09 | H10: Сум | J10: =SUM(J2:J9) -> 0 | K10: =J10-G10-D10 -> -1.9904881e+09

Sheet "BIT 2026"  MILANO
A1: № | B1: Название выставки | C1: Дата проведения | D1: Размер площади | E1: Стоимость площади | F1: Валюта | G1: Стоимость стенда | H1: Валюта | I1: Участники выставки | J1: Сумма | K1: Валюта | L1: Прибыль
A2: 4 | B2: "BIT 2026" MILANO | C2: 10-12 февраля | D2: 64 кв м | E2: 20005 | F2: EURO | G2: 4637000 | H2: Рубль | I2: OOO "FINANCE WORLD SERVICES" | J2: 15000000 | K2: Сум | N2: евро | O2: 13981
I3: OOO AFSONA TRAVEL | J3: 15000000 | N3: рубль | O3: 163.03
I4: Zumrad Travel | J4: 7500000
I5: Anur Tour | J5: 15000000
A6: Итог | D6: =E2*O2 -> 279689905 | F6: Сум | G6: =G2*O3 -> 755970110 | H6: Сум | J6: =J2+J3+J4+J5 -> 52500000 | K6: =J6-G6-D6 -> -983160015

Sheet "Danish Travel show 2026"
A1: № | B1: Название выставки | C1: Дата проведения | D1: Размер площади | E1: Стоимость площади | F1: Валюта | G1: Стоимость стенда | H1: Валюта | I1: Участники выставки | J1: Сумма | K1: Валюта | L1: Прибыль
A2: 5 | B2: "Danish Travel show 2026" | C2: 20-22 февраля | D2: 48 кв м | E2: 8423.73 | F2: EURO | G2: 63500 | H2: EURO | I2: OOO "Premium Trans"/Orient Star | J2: 10000000 | K2: Сум | N2: евро | O2: 13981
I3: "Miramax Travel Management" | J3: 10000000
I4: "Tashkent Travel Hub" | J4: 10000000
A5: Итог | D5: =E2*O2 -> 1.1777217e+08 | F5: Сум | G5: =G2*O2 -> 887793500 | H5: Сум | J5: =SUM(J2:J4) -> 30000000 | K5: =J5-G5-D5 -> -9.7556567e+08

Sheet "B-Travel"
A1: № | B1: Название выставки | C1: Дата проведения | D1: Размер площади | E1: Стоимость площади | F1: Валюта | G1: Стоимость стенда | H1: Валюта | I1: Участники выставки | J1: Сумма | K1: Валюта | L1: Прибыль
A2: 6 | B2: "B-Travel" | C2: 20-22 марта | D2: 94 кв м | E2: 25941 | F2: EURO | G2: 64775 | H2: EURO | I2: OOO "Global Explore" | J2: 10000000 | K2: Сум
I3: OOO "El Mundo Tour" | J3: 10000000
I4: OOO "Samarkand Touristic Centre" | J4: 10000000 | N4: евро | O4: 13981
I5: OOO "Premium Trans"/Orient Star | J5: 10000000
I6: OOO "Zamin DMC" | J6: 10000000
I7: OOO "Smart Tours"/Travellers | J7: 10000000
I8: "Uzbekistan Airways" | J8: 100000000
A9: Итог | D9: =E2*O4 -> 362681121 | F9: Сум | G9: =G2*O4 -> 905619275 | H9: Сум | J9: =SUM(J2:J8) -> 160000000 | K9: =J9-G9-D9 -> -1108300396

Sheet "SATTE-2026"
A1: № | B1: Название выставки | C1: Дата проведения | D1: Размер площади | E1: Стоимость площади | F1: Валюта | G1: Стоимость стенда | H1: Валюта | I1: Участники выставки | J1: Сумма | K1: Валюта | L1: Прибыль
A2: 7 | B2: "SATTE-2026" | C2: 25-27 февраля | D2: 120 кв м | E2: 81604.08 | F2: USD | G2: 96375.51 | H2: USD | I2: "Uzbekistan Airways" | J2: 70000000 | K2: Сум | N2: дол | O2: 11930
I3: "Akfa Dream World"/Hilton | J3: 15000000
I4: OOO "My Frieghter"/Centrum Air | J4: 15000000
I5: OOO "Kazin DMC" | J5: 15000000
I6: OOO "BEYOND DMC" | J6: 15000000
I7: OOO "ENJOY TRAVEL" | J7: 15000000
I8: OK "EAST ASIA POINT" | J8: 15000000
I9: Rezbook global | J9: 15000000
A10: Итог | D10: =E2*O2 -> 9.7353667e+08 | F10: Сум | G10: =G2*O2 -> 1.1497598e+09 | H10: Сум | J10: =SUM(J2:J9) -> 175000000 | K10: =J10-G10-D10 -> -1.9482965e+09

Sheet "OTM Mumbai 2026"
A1: № | B1: Название выставки | C1: Дата проведения | D1: Размер площади | E1: Стоимость площади | F1: Валюта | G1: Стоимость стенда | H1: Валюта | I1: Участники выставки | J1: Сумма | K1: Валюта | L1: Прибыль
A2: 8 | B2: "OTM Mumbai 2026" | C2: 5-7 февраля | D2: 72 кв м | E2: 47152.8 | F2: USD | G2: 57324.4 | H2: USD | I2: "Enjoy Travel" | J2: 10000000 | K2: Сум
I3: OK "ONS Travels" | J3: 10000000 | N3: дол | O3: 11930
I4: OOO "Akfa Dream World"/Hilton | J4: 10000000
I5: OOO "FAYZ GRAND MINION"/Bazar Travel | J5: 10000000
I6: Akbar Travel | J6: 10000000
A7: Итог | D7: =E2*O3 -> 562532904 | F7: Сум | G7: =G2*O3 -> 683880092 | H7: Сум | J7: =SUM(J2:J6) -> 50000000 | K7: =J7-G7-D7 -> -1196412996

Sheet "ITB-2026" Берлин
A1: № | B1: Название выставки | C1: Дата проведения | D1: Размер площади | E1: Стоимость площади | F1: Валюта | G1: Стоимость стенда | H1: Валюта | I1: Участники выставки | J1: Сумма | K1: Валюта | L1: Прибыль
A2: 9 | B2: "ITB-2026" Берлин | C2: 3-5 марта | D2: 202 кв м | E2: 59000 | F2: EURO | G2: 119900 | H2: EURO | I2: "International Caravan Travel Service Co.,Ltd" | J2: 40000000 | K2: Сум | N2: евро | O2: 13981
I3: "CREATIVE TOURS" MCHJ | J3: 40000000
I4: "GEO TOUR SERVICE" | J4: 40000000
I5: "ANTIQUE TRAVEL EXPERTS" OK | J5: 40000000
I6: "TRAVEL FACTORY" MCHJ | J6: 40000000
I7: "SITARA INTERNATIONAL LTD" MCHJ | J7: 40000000
I8: "SEZAM TRAVEL" MCHJ | J8: 40000000
I9: "PEOPLETRAVEL" MCHJ | J9: 40000000
I10: "AKFA DREAM WORLD" MCHJ | J10: 40000000
I11: "DARVESH TUR SERVS" MCHJ | J11: 40000000
I12: OOO "Premium Trans"/Orient Star | J12: 40000000
I13: OOO "GLOBAL EXPLORE"/Uzbekistan Discovery | J13: 40000000
I14: OOO "MEGA TOUR" | J14: 40000000
... I17: OOO "IMRAN TOURS" | J17: 40000000
A18: Итог | D18: =E2*O2 -> 824879000 | F18: Сум | G18: =G2*O2 -> 1676321900 | H18: Сум | J18: =SUM(J2:J17) -> 640000000 | K18: =J18-G18-D18 -> -1861200900

Sheet "MITT 2026"
A1: № | B1: Название выставки | C1: Дата проведения | D1: Размер площади | E1: Стоимость площади | F1: Валюта | G1: Стоимость стенда | H1: Валюта | I1: Участники выставки | J1: Сумма | K1: Валюта | L1: Прибыль
A2: 10 | B2: "MITT 2026" | C2: 11-13 марта | D2: 135 кв м | E2: 116713 | F2: USD | G2: 8235542 | H2: Рубль | I2: OOO "Dolores Travel Services" | J2: 30000000 | K2: Сум | N2: рубль | O2: 163.03
I3: OOO "CENTRAL ASIA TRAVEL" | J3: 30000000 | N3: дол | O3: 11930
I4: OOO "UKTAMXON TOUR" | J4: 30000000
I5: OOO "Samarkand Touristic Centre" | J5: 30000000
I6: "Uzbekistan Airways" | J6: 120000000
I7: OOO "Premium Trans"/Orient Star | J7: 30000000
I8: Arda Khiva | J8: 0
I9: Inter MICE Asia | J9: 30000000
I10: TIMURWAY | J10: 30000000
A11: Итог | D11: =E2*O3 -> 1392386090 | F11: Сум | G11: =G2*O2 -> 1.3426404e+09 | H11: Сум | J11: =SUM(J2:J10) -> 330000000 | K11: =J11-G11-D11 -> -2.4050265e+09

Sheet "ITB China - 2026"
A1: № | B1: Название выставки | C1: Дата проведения | D1: Размер площади | E1: Стоимость площади | F1: Валюта | G1: Стоимость стенда | H1: Валюта | I1: Участники выставки | J1: Сумма | K1: Валюта | L1: Прибыль
A2: 11 | B2: "ITB China - 2026" | C2: 26-28 мая | D2: 81 кв м | E2: 23000 | F2: USD | G2: 56127 | H2: USD | I2: OOO "Asia trip" | J2: ='реестр 2026'!K88 -> 20000000 | K2: Сум
I3: OOO "IMRAN TOURS" | J3: ='реестр 2026'!K89 -> 20000000 | N3: дол | O3: 11930
I4: "BEYOND EXPECTATIONS" | J4: ='реестр 2026'!K90 -> 20000000
I5: OOO "Afsona Travel" | J5: ='реестр 2026'!K91 -> 20000000
I6: OOO "Smart Tours" | J6: ='реестр 2026'!K92 -> 20000000
I7: OOO "Premium Trans"/Orient Star | J7: ='реестр 2026'!K93 -> 20000000
I8: OOO "Samarkand Touristic Centre" | J8: ='реестр 2026'!K94 -> 20000000
I9: "UZTURINVESTMENT AND DEVELOPMENT" | J9: ='реестр 2026'!K95 -> 20000000
A10: Итог | D10: =E2*O3 -> 274390000 | F10: Сум | G10: =G2*O3 -> 669595110 | H10: Сум | J10: =SUM(J2:J9) -> 160000000 | K10: =J10-G10-D10 -> -783985110

Sheet "KITF-2026"
A1: № | B1: Название выставки | C1: Дата проведения | D1: Размер площади | E1: Стоимость площади | F1: Валюта | G1: Стоимость стенда | H1: Валюта | I1: Участники выставки | J1: Сумма | K1: Валюта | L1: Прибыль
A2: 12 | B2: "KITF-2026" | C2: 22-24 апреля | D2: 56 кв м | E2: 21806.74 | F2: USD | G2: 40350 | H2: USD | I2: OOO "Samarkand Touristic Centre" | J2: 15000000 | K2: Сум | N2: дол | O2: 11930
I3: "OKS TOURS" | J3: 15000000
I4: Uzairways | J4: 120000000
I5: Hotel Pro/Arda Xiva | J5: 0
A6: Итог | D6: =E2*O2 -> 2.6015441e+08 | F6: Сум | G6: =G2*O2 -> 481375500 | H6: Сум | J6: =SUM(J2:J5) -> 150000000 | K6: =J6-G6-D6 -> -5.9152991e+08

Sheet BITF-2026
A1: № | B1: Название выставки | C1: Дата проведения | D1: Размер площади | E1: Стоимость площади | F1: Валюта | G1: Стоимость стенда | H1: Валюта | I1: Участники выставки | J1: Сумма | K1: Валюта | L1: Прибыль
A2: 13 | B2: BITF-2026 | C2: 30 апреля по 2 мая | D2: 48 кв м | E2: 9108.6 | F2: USD | G2: 24300 | H2: USD | I2: Zilol Sanatoriya | J2: 8000000 | K2: Сум | N2: дол | O2: 11930
I3: Tour Link/Premium Trans | J3: 8000000
I4: Cheksiz Trip | J4: 8000000
I5: Sherobod Turizm | J5: 8000000
I6: TIC Travel | J6: 8000000
A7: Итог | D7: =E2*O2 -> 108665598 | F7: Сум | G7: =G2*O2 -> 289899000 | H7: Сум | J7: =SUM(J3:J6) -> 32000000 | K7: =J7-G7-D7 -> -366564598

Sheet IMEX - 2026
A1: № | B1: Название выставки | C1: Дата проведения | D1: Размер площади | E1: Стоимость площади | F1: Валюта | G1: Стоимость стенда | H1: Валюта | I1: Участники выставки | J1: Сумма | K1: Валюта | L1: Прибыль
A2: 1 | B2: IMEX - 2026 | C2: 19-21 мая | D2: 30 кв м | E2: 24115 | F2: EURO | G2: 38153 | H2: EURO | I2: Silk Road Samarkand | J2: 60000000 | K2: Сум | N2: евро | O2: 13981
I3: OOO "ZAMIN DMC"/Asia Luxe | J3: 40000000
I4: Tour Link/Premium Trans | J4: 40000000
I5: El Mundo | J5: 40000000
A6: Итог | D6: =E2*O2 -> 337151815 | F6: Сум | G6: =G2*O2 -> 533417093 | H6: Сум | J6: =SUM(J2:J5) -> 180000000 | K6: =J6-G6-D6 -> -690568908
